<?xml version="1.0" ?>
<!-- =================================================================================== -->
<!-- |    This document was autogenerated by xacro from one_link_geometry.urdf.xacro   | -->
<!-- |    EDITING THIS FILE BY HAND IS NOT RECOMMENDED                                 | -->
<!-- =================================================================================== -->
<robot name="one_link_geometry" xmlns:xacro="http://ros.org/wiki/xacro">
  <!-- unit it is in meter -->
  <!-- This material is for RViZ not in Gazebo -->
  <material name="blue">
    <color rgba="0 0 0.8 1"/>
  </material>
  <material name="black">
    <color rgba="0 0 0 1"/>
  </material>
  <material name="white">
    <color rgba="1 1 1 1"/>
  </material>
  <!-- This is the wolrd / ground link to fix the robot to the ground -->
  <link name="world"/>
  <!-- This is the joint that connect the link1 with ground-->
  <joint name="joint1" type="revolute">
    <axis xyz="0 0 0"/>
    <limit effort="1000.0" lower="0.0" upper="3.14159265359" velocity="1.0"/>
    <origin xyz="0 0 0"/>
    <parent link="world"/>
    <child link="link1"/>
  </joint>
  <!-- One Link -->
  <link name="link1">
    <collision>
      <origin rpy="0 0 0" xyz="0 0 0.25"/>
      <geometry>
        <box size="0.02 0.02 0.5"/>
      </geometry>
    </collision>
    <visual>
      <origin rpy="0 0 0" xyz="0 0 0.25"/>
      <geometry>
        <box size="0.02 0.02 0.5"/>
      </geometry>
    </visual>
    <inertial>
      <origin rpy="0 0 0" xyz="0 0 0"/>
      <mass value="0.5"/>
      <inertia ixx="0.0104333333333" ixy="0.0" ixz="0.0" iyy="0.0104333333333" iyz="0.0" izz="3.33333333333e-05"/>
    </inertial>
  </link>
</robot>

